<?xml version="1.0" ?>
<!-- =================================================================================== -->
<!-- |    This document was autogenerated by xacro from robot.urdf.xacro               | -->
<!-- |    EDITING THIS FILE BY HAND IS NOT RECOMMENDED                                 | -->
<!-- =================================================================================== -->
<robot name="my_robot">
  <material name="white">
    <color rgba="1 1 1 1"/>
  </material>
  <material name="orange">
    <color rgba="1 0.5 0 1"/>
  </material>
  <material name="blue">
    <color rgba="0 0 1 1"/>
  </material>
  <material name="black">
    <color rgba="0 0 0 1"/>
  </material>
  <link name="footbase_link"/>
  <link name="base_link"/>
  <!-- Fixed joint with offset -->
  <joint name="base_to_offset" type="fixed">
    <parent link="footbase_link"/>
    <child link="base_link"/>
    <origin rpy="0 0 0" xyz="0.0 0.0 0.85"/>
    <!-- This is the offset: 10cm forward, 20cm up -->
  </joint>
  <joint name="kropp_joint" type="fixed">
    <parent link="base_link"/>
    <child link="kropp"/>
    <!-- Offset for kropp ift. base_link (brukes til å finjustere modellens referansepunkt). -->
    <origin xyz="0 0.25 0"/>
  </joint>
  <link name="kropp">
    <!-- Kropp: visuell geometri og kollisjon holdes identiske (en boks) for stabil og rask simulering.
             Inertial beregnes via xacro-makro for konsistens når dimensjoner endres. -->
    <visual>
      <origin xyz="0.0 0.0 0.0"/>
      <geometry>
        <box size="0.2 0.3 0.1"/>
      </geometry>
      <material name="white"/>
    </visual>
    <collision>
      <origin xyz="0.0 0.0 0.0"/>
      <geometry>
        <box size="0.2 0.3 0.1"/>
      </geometry>
    </collision>
    <inertial>
      <origin rpy="0 0 0" xyz="0 0 0"/>
      <mass value="0.5"/>
      <inertia ixx="0.004166666666666667" ixy="0.0" ixz="0.0" iyy="0.0020833333333333337" iyz="0.0" izz="0.005416666666666667"/>
    </inertial>
  </link>
  <gazebo reference="kropp">
    <material>Gazebo/White</material>
  </gazebo>
  <!-- Gimbal ("gimble")
         Ønsket: blå stand er fast, og orange boks roterer (yaw rundt Z, pitch rundt X). -->
  <joint name="gimble_stand_joint" type="fixed">
    <parent link="kropp"/>
    <child link="gimble_stand"/>
    <!-- kropp er 0.1 høy (±0.05). Stand er 0.1 lang (±0.05). Senter på stand plasseres derfor på z=0.10. -->
    <origin rpy="0 0 0" xyz="0 0 0.10"/>
  </joint>
  <link name="gimble_stand">
    <visual>
      <geometry>
        <cylinder length="0.1" radius="0.02"/>
      </geometry>
      <material name="blue"/>
    </visual>
    <collision>
      <geometry>
        <cylinder length="0.1" radius="0.02"/>
      </geometry>
    </collision>
    <inertial>
      <origin rpy="0 0 0" xyz="0 0 0"/>
      <mass value="0.1"/>
      <inertia ixx="9.333333333333334e-05" ixy="0.0" ixz="0.0" iyy="9.333333333333334e-05" iyz="0.0" izz="2e-05"/>
    </inertial>
  </link>
  <gazebo reference="gimble_stand">
    <material>Gazebo/Blue</material>
  </gazebo>
  <joint name="gimble_yaw_joint" type="continuous">
    <parent link="gimble_stand"/>
    <child link="gimble_yaw"/>
    <!-- Pivot på toppen av stand (stand topp = +0.05 i stand-rammen). -->
    <origin rpy="0 0 0" xyz="0 0 0.05"/>
    <axis xyz="0 0 1"/>
    <limit effort="1.0" velocity="1.0"/>
  </joint>
  <link name="gimble_yaw">
    <inertial>
      <origin rpy="0 0 0" xyz="0 0 0"/>
      <mass value="0.01"/>
      <inertia ixx="4.0000000000000003e-07" ixy="0.0" ixz="0.0" iyy="4.0000000000000003e-07" iyz="0.0" izz="4.0000000000000003e-07"/>
    </inertial>
  </link>
  <!-- Pitch begrenses til ±15 grader. -->
  <joint name="gimble_pitch_joint" type="revolute">
    <parent link="gimble_yaw"/>
    <child link="lidar"/>
    <origin rpy="0 0 0" xyz="0 0 0"/>
    <axis xyz="1 0 0"/>
    <limit effort="1.0" lower="-0.261799" upper="0.261799" velocity="1.0"/>
  </joint>
  <joint name="venstre_hjul_joint" type="continuous">
    <parent link="kropp"/>
    <child link="venstre_hjul"/>
    <origin xyz="-0.1025 0.0 -0.05"/>
    <axis xyz="1 0 0"/>
    <limit effort="1.0" velocity="10.0"/>
  </joint>
  <link name="venstre_hjul">
    <visual>
      <origin rpy="1.57079632679 0 1.57079632679"/>
      <geometry>
        <cylinder length="0.005" radius="0.035"/>
      </geometry>
      <material name="black"/>
    </visual>
    <collision>
      <origin rpy="1.57079632679 0 1.57079632679"/>
      <geometry>
        <cylinder length="0.005" radius="0.035"/>
      </geometry>
    </collision>
    <inertial>
      <origin rpy="0 0 0" xyz="0 0 0"/>
      <mass value="0.1"/>
      <inertia ixx="3.0833333333333335e-05" ixy="0.0" ixz="0.0" iyy="3.0833333333333335e-05" iyz="0.0" izz="6.125000000000001e-05"/>
    </inertial>
  </link>
  <gazebo reference="venstre_hjul">
    <material>Gazebo/Black</material>
  </gazebo>
  <joint name="høyre_hjul_joint" type="continuous">
    <parent link="kropp"/>
    <child link="høyre_hjul"/>
    <origin xyz="0.1025 0 -0.05"/>
    <axis xyz="1 0 0"/>
    <limit effort="1.0" velocity="10.0"/>
  </joint>
  <link name="høyre_hjul">
    <visual>
      <origin rpy="1.57079632679 0 1.57079632679"/>
      <geometry>
        <cylinder length="0.005" radius="0.035"/>
      </geometry>
      <material name="black"/>
    </visual>
    <collision>
      <origin rpy="1.57079632679 0 1.57079632679"/>
      <geometry>
        <cylinder length="0.005" radius="0.035"/>
      </geometry>
    </collision>
    <inertial>
      <origin rpy="0 0 0" xyz="0 0 0"/>
      <mass value="0.1"/>
      <inertia ixx="3.0833333333333335e-05" ixy="0.0" ixz="0.0" iyy="3.0833333333333335e-05" iyz="0.0" izz="6.125000000000001e-05"/>
    </inertial>
  </link>
  <gazebo reference="høyre_hjul">
    <material>Gazebo/Black</material>
  </gazebo>
  <!-- Støttehjul (caster)
         For en enkel plattform brukes et fast montert "kulehjul" (sphere) for stabil støtte.
         Plasser Z slik at støttehjulet berører bakken på samme høyde som drivhjulene. -->
  <joint name="cast_hjul_joint" type="fixed">
    <parent link="kropp"/>
    <child link="cast_hjul"/>
    <origin xyz="0 -0.12 -0.055"/>
  </joint>
  <link name="cast_hjul">
    <visual>
      <geometry>
        <sphere radius="0.03"/>
      </geometry>
      <material name="black"/>
    </visual>
    <collision>
      <geometry>
        <sphere radius="0.03"/>
      </geometry>
    </collision>
    <inertial>
      <origin rpy="0 0 0" xyz="0 0 0"/>
      <mass value="0.1"/>
      <inertia ixx="3.600000000000001e-05" ixy="0.0" ixz="0.0" iyy="3.600000000000001e-05" iyz="0.0" izz="3.600000000000001e-05"/>
    </inertial>
  </link>
  <gazebo reference="cast_hjul">
    <material>Gazebo/Black</material>
    <!--friksjons coff-->
    <mu1 value="0.000001"/>
    <mu2 value="0.000001"/>
  </gazebo>
  <link name="lidar">
    <visual>
      <!-- Løft boksen litt opp slik at rotasjon skjer i bunn av boksen. -->
      <origin rpy="0 0 0" xyz="0 0 0.0125"/>
      <geometry>
        <!-- Skalert kopi av kropp-boksen (0.2 0.3 0.1) i 1/4 størrelse. -->
        <box size="0.05 0.075 0.025"/>
      </geometry>
      <material name="orange"/>
    </visual>
    <collision>
      <origin rpy="0 0 0" xyz="0 0 0.0125"/>
      <geometry>
        <box size="0.05 0.075 0.025"/>
      </geometry>
    </collision>
    <inertial>
      <origin rpy="0 0 0" xyz="0 0 0.0125"/>
      <mass value="0.1"/>
      <inertia ixx="5.208333333333334e-05" ixy="0.0" ixz="0.0" iyy="2.6041666666666672e-05" iyz="0.0" izz="6.770833333333333e-05"/>
    </inertial>
  </link>
  <gazebo reference="lidar">
    <material>Gazebo/Orange</material>
  </gazebo>

  <!--> Control units </!-->
  <!-->
  <xacro:include filename="../gazebo_control.xacro"/>
  </!-->
    <plugin filename="gz-sim-diff-drive-system" name="gz::sim::systems::DiffDrive">
        <left_joint>venstre_hjul_joint</left_joint>
        <right_joint>høyre_hjul_joint</right_joint>
        <wheel_separation>0.205</wheel_separation>
        <wheel_radius>0.035</wheel_radius>
        <odom_publish_frequency>1</odom_publish_frequency>
        <topic>cmd_vel</topic>
        <odom_topic>odom</odom_topic>
        <tf_topic>tf</tf_topic>
        <frame_id>odom</frame_id>
        <max_linear_acceleration>1.0</max_linear_acceleration>
        <min_linear_acceleration>-1.0</min_linear_acceleration>
        <max_angular_acceleration>2.0</max_angular_acceleration>
        <min_angular_acceleration>-2.0</min_angular_acceleration>
      </plugin>

      <!-- Joint State Publisher -->
      <plugin filename="gz-sim-joint-state-publisher-system" name="gz::sim::systems::JointStatePublisher"/>
  
  <!-- ============================================ -->
    <!--  Keyboard → cmd_vel  (TriggeredPublisher)    -->
    <!--  Key codes: W=87 S=83 A=65 D=68              -->
    <!--  Arrow keys: Up=16777235 Down=16777237        -->
    <!--              Left=16777234 Right=16777236      -->
    <!-- ============================================ -->

    <!-- W key / Up arrow → Forward -->
    <plugin filename="gz-sim-triggered-publisher-system" name="gz::sim::systems::TriggeredPublisher">
      <input type="gz.msgs.Int32" topic="/keyboard/keypress">
        <match field="data">87</match>
      </input>
      <output type="gz.msgs.Twist" topic="/cmd_vel">
        linear: {x: 0.5}, angular: {z: 0.0}
      </output>
    </plugin>
    
    <plugin filename="gz-sim-triggered-publisher-system" name="gz::sim::systems::TriggeredPublisher">
      <input type="gz.msgs.Int32" topic="/keyboard/keypress">
        <match field="data">16777235</match>
      </input>
      <output type="gz.msgs.Twist" topic="/cmd_vel">
        linear: {x: 0.5}, angular: {z: 0.0}
      </output>
    </plugin>

    <!-- S key / Down arrow → Backward -->
    <plugin filename="gz-sim-triggered-publisher-system" name="gz::sim::systems::TriggeredPublisher">
      <input type="gz.msgs.Int32" topic="/keyboard/keypress">
        <match field="data">83</match>
      </input>
      <output type="gz.msgs.Twist" topic="/cmd_vel">
        linear: {x: -0.5}, angular: {z: 0.0}
      </output>
    </plugin>
    
    <plugin filename="gz-sim-triggered-publisher-system" name="gz::sim::systems::TriggeredPublisher">
      <input type="gz.msgs.Int32" topic="/keyboard/keypress">
        <match field="data">16777237</match>
      </input>
      <output type="gz.msgs.Twist" topic="/cmd_vel">
        linear: {x: -0.5}, angular: {z: 0.0}
      </output>
    </plugin>

    <!-- A key / Left arrow → Turn Left -->
    <plugin filename="gz-sim-triggered-publisher-system" name="gz::sim::systems::TriggeredPublisher">
      <input type="gz.msgs.Int32" topic="/keyboard/keypress">
        <match field="data">65</match>
      </input>
      <output type="gz.msgs.Twist" topic="/cmd_vel">
        linear: {x: 0.0}, angular: {z: 0.5}
      </output>
    </plugin>
    <plugin filename="gz-sim-triggered-publisher-system" name="gz::sim::systems::TriggeredPublisher">
      <input type="gz.msgs.Int32" topic="/keyboard/keypress">
        <match field="data">16777234</match>
      </input>
      <output type="gz.msgs.Twist" topic="/cmd_vel">
        linear: {x: 0.0}, angular: {z: 0.5}
      </output>
    </plugin>

    <!-- D key / Right arrow → Turn Right -->
    <plugin filename="gz-sim-triggered-publisher-system" name="gz::sim::systems::TriggeredPublisher">
      <input type="gz.msgs.Int32" topic="/keyboard/keypress">
        <match field="data">68</match>
      </input>
      <output type="gz.msgs.Twist" topic="/cmd_vel">
        linear: {x: 0.0}, angular: {z: -0.5}
      </output>
    </plugin>
    
    <plugin filename="gz-sim-triggered-publisher-system" name="gz::sim::systems::TriggeredPublisher">
      <input type="gz.msgs.Int32" topic="/keyboard/keypress">
        <match field="data">16777236</match>
      </input>
      <output type="gz.msgs.Twist" topic="/cmd_vel">
        linear: {x: 0.0}, angular: {z: -0.5}
      </output>
    </plugin>

</robot>
