<?xml version="1.10" ?>
<sdf version="1.10">

    
    <!-- ========================= -->
    <!--   Two-Wheeled Robot        -->
    <!-- ========================= -->
    <model name="two_wheel_robot">


      <pose>0 0 0.1 0 0 0</pose>

        <plugin filename="gz-sim-sensors-system" name="gz::sim::systems::Sensors">
          <render_engine>ogre2</render_engine>
        </plugin>


      <!-- ===== Chassis (body) ===== -->
      <link name="chassis">
        <pose>0 0 0.05 0 0 0</pose>
        <inertial>
          <mass>5.0</mass>
          <inertia>
            <ixx>0.0417</ixx>
            <iyy>0.0667</iyy>
            <izz>0.0917</izz>
            <ixy>0</ixy>
            <ixz>0</ixz>
            <iyz>0</iyz>
          </inertia>
        </inertial>
        <collision name="chassis_collision">
          <geometry>
            <box>
              <size>0.4 0.3 0.15</size>
            </box>
          </geometry>
        </collision>
        <visual name="chassis_visual">
          <geometry>
            <box>
              <size>0.4 0.3 0.15</size>
            </box>
          </geometry>
          <material>
            <ambient>0.1 0.1 0.8 1</ambient>
            <diffuse>0.2 0.2 0.9 1</diffuse>
            <specular>0.5 0.5 0.5 1</specular>
          </material>
        </visual>
      </link>

      <!-- ===== Caster Wheel (front support) ===== -->
      <link name="caster_wheel">
        <pose>0.15 0 -0.05 0 0 0</pose>
        <inertial>
          <mass>0.2</mass>
          <inertia>
            <ixx>0.00008</ixx>
            <iyy>0.00008</iyy>
            <izz>0.00008</izz>
            <ixy>0</ixy>
            <ixz>0</ixz>
            <iyz>0</iyz>
          </inertia>
        </inertial>
        <collision name="caster_collision">
          <geometry>
            <sphere>
              <radius>0.04</radius>
            </sphere>
          </geometry>
          <surface>
            <friction>
              <ode>
                <mu>0.0</mu>
                <mu2>0.0</mu2>
              </ode>
            </friction>
          </surface>
        </collision>
        <visual name="caster_visual">
          <geometry>
            <sphere>
              <radius>0.04</radius>
            </sphere>
          </geometry>
          <material>
            <ambient>0.3 0.3 0.3 1</ambient>
            <diffuse>0.4 0.4 0.4 1</diffuse>
          </material>
        </visual>
      </link>

      <joint name="caster_joint" type="fixed">
        <parent>chassis</parent>
        <child>caster_wheel</child>
      </joint>

      <!-- ===== Left Wheel ===== -->
      <link name="left_wheel">
        <pose>-0.1 0.175 -0.01 -1.5708 0 0</pose>
        <inertial>
          <mass>0.5</mass>
          <inertia>
            <ixx>0.00065</ixx>
            <iyy>0.00065</iyy>
            <izz>0.00113</izz>
            <ixy>0</ixy>
            <ixz>0</ixz>
            <iyz>0</iyz>
          </inertia>
        </inertial>
        <collision name="left_wheel_collision">
          <geometry>
            <cylinder>
              <radius>0.08</radius>
              <length>0.04</length>
            </cylinder>
          </geometry>
          <surface>
            <friction>
              <ode>
                <mu>1.0</mu>
                <mu2>1.0</mu2>
              </ode>
            </friction>
          </surface>
        </collision>
        <visual name="left_wheel_visual">
          <geometry>
            <cylinder>
              <radius>0.08</radius>
              <length>0.04</length>
            </cylinder>
          </geometry>
          <material>
            <ambient>0.1 0.1 0.1 1</ambient>
            <diffuse>0.2 0.2 0.2 1</diffuse>
          </material>
        </visual>
      </link>

      <joint name="left_wheel_joint" type="revolute">
        <parent>chassis</parent>
        <child>left_wheel</child>
        <axis>
          <xyz>0 0 1</xyz>
          <limit>
            <lower>-1.79769e+308</lower>
            <upper>1.79769e+308</upper>
          </limit>
        </axis>
      </joint>

      <!-- ===== Right Wheel ===== -->
      <link name="right_wheel">
        <pose>-0.1 -0.175 -0.01 -1.5708 0 0</pose>
        <inertial>
          <mass>0.5</mass>
          <inertia>
            <ixx>0.00065</ixx>
            <iyy>0.00065</iyy>
            <izz>0.00113</izz>
            <ixy>0</ixy>
            <ixz>0</ixz>
            <iyz>0</iyz>
          </inertia>
        </inertial>
        <collision name="right_wheel_collision">
          <geometry>
            <cylinder>
              <radius>0.08</radius>
              <length>0.04</length>
            </cylinder>
          </geometry>
          <surface>
            <friction>
              <ode>
                <mu>1.0</mu>
                <mu2>1.0</mu2>
              </ode>
            </friction>
          </surface>
        </collision>
        <visual name="right_wheel_visual">
          <geometry>
            <cylinder>
              <radius>0.08</radius>
              <length>0.04</length>
            </cylinder>
          </geometry>
          <material>
            <ambient>0.1 0.1 0.1 1</ambient>
            <diffuse>0.2 0.2 0.2 1</diffuse>
          </material>
        </visual>
      </link>

      <joint name="right_wheel_joint" type="revolute">
        <parent>chassis</parent>
        <child>right_wheel</child>
        <axis>
          <xyz>0 0 1</xyz>
          <limit>
            <lower>-1.79769e+308</lower>
            <upper>1.79769e+308</upper>
          </limit>
        </axis>
      </joint>

      <!-- ===== Camera Link ===== -->
      <link name="camera_link">
        <pose>0.2 0 0.1 0 0 0</pose>
        <inertial>
          <mass>0.1</mass>
          <inertia>
            <ixx>0.00001</ixx>
            <iyy>0.00001</iyy>
            <izz>0.00001</izz>
            <ixy>0</ixy>
            <ixz>0</ixz>
            <iyz>0</iyz>
          </inertia>
        </inertial>
        <visual name="camera_visual">
          <geometry>
            <box>
              <size>0.03 0.06 0.03</size>
            </box>
          </geometry>
          <material>
            <ambient>0.8 0.1 0.1 1</ambient>
            <diffuse>0.9 0.2 0.2 1</diffuse>
          </material>
        </visual>
        <sensor name="camera" type="camera">
          <always_on>true</always_on>
          <update_rate>10</update_rate>
          <visualize>true</visualize>
          <topic>camera_image</topic>
          <camera>
            <horizontal_fov>1.151917</horizontal_fov>
            <image>
              <width>1080</width>
              <height>720</height>
              <format>R8G8B8</format>
            </image>
            <clip>
              <near>0.02</near>
              <far>300</far>
            </clip>
          </camera>
        </sensor>
      </link>

      <joint name="camera_joint" type="fixed">
        <parent>chassis</parent>
        <child>camera_link</child>
      </joint>

      <!-- ===== Lidar Link ===== -->
      <link name="lidar_link">
        <pose>0 0 0.18 0 0 0</pose>
        <inertial>
          <mass>0.2</mass>
          <inertia>
            <ixx>0.00005</ixx>
            <iyy>0.00005</iyy>
            <izz>0.00005</izz>
            <ixy>0</ixy>
            <ixz>0</ixz>
            <iyz>0</iyz>
          </inertia>
        </inertial>
        <visual name="lidar_visual">
          <geometry>
            <cylinder>
              <radius>0.04</radius>
              <length>0.04</length>
            </cylinder>
          </geometry>
          <material>
            <ambient>0.1 0.8 0.1 1</ambient>
            <diffuse>0.2 0.9 0.2 1</diffuse>
          </material>
        </visual>
        <sensor name="lidar" type="gpu_lidar">
          <always_on>true</always_on>
          <update_rate>30</update_rate>
          <visualize>true</visualize>
          <topic>scan_gpu</topic>
          <lidar>
            <scan>
              <horizontal>
                <samples>360</samples>
                <resolution>1</resolution>
                <min_angle>-3.14159</min_angle>
                <max_angle>3.14159</max_angle>
              </horizontal>
              <vertical>
                <samples>1</samples>
                <resolution>1</resolution>
                <min_angle>0</min_angle>
                <max_angle>0</max_angle>
              </vertical>
            </scan>
            <range>
              <min>0.5</min>
              <max>12.0</max>
              <resolution>0.01</resolution>
            </range>
            <noise>
              <type>gaussian</type>
              <mean>0</mean>
              <stddev>0.01</stddev>
            </noise>
          </lidar>
        </sensor>
      </link>

      <joint name="lidar_joint" type="fixed">
        <parent>chassis</parent>
        <child>lidar_link</child>
      </joint>

      <!-- ===== Differential Drive Plugin ===== -->
      <plugin filename="gz-sim-diff-drive-system" name="gz::sim::systems::DiffDrive">
        <left_joint>left_wheel_joint</left_joint>
        <right_joint>right_wheel_joint</right_joint>
        <wheel_separation>0.35</wheel_separation>
        <wheel_radius>0.08</wheel_radius>
        <odom_publish_frequency>50</odom_publish_frequency>
        <topic>cmd_vel</topic>
        <odom_topic>odom</odom_topic>
        <tf_topic>tf</tf_topic>
        <frame_id>odom</frame_id>
        <child_frame_id>chassis</child_frame_id>
        <max_linear_acceleration>1.0</max_linear_acceleration>
        <min_linear_acceleration>-1.0</min_linear_acceleration>
        <max_angular_acceleration>2.0</max_angular_acceleration>
        <min_angular_acceleration>-2.0</min_angular_acceleration>
      </plugin>

      <!-- Joint State Publisher -->
      <plugin filename="gz-sim-joint-state-publisher-system" name="gz::sim::systems::JointStatePublisher"/>

    </model>

</sdf>

